2022-01-01 13:49:14,683 INFO: 
APPLICATION HAS BEEN DEPLOYED [in /home/jagdpanther/EPAM/snaketests/src/__init__.py:110]

2022-01-01 13:55:34,746 INFO: 
APPLICATION HAS BEEN DEPLOYED [in /home/jagdpanther/EPAM/snaketests/src/__init__.py:115]

2022-01-01 14:01:13,317 INFO: 
APPLICATION HAS BEEN DEPLOYED [in /home/jagdpanther/EPAM/snaketests/src/__init__.py:115]

2022-01-01 14:01:48,914 ERROR: 
Exception on /auth/register [POST] [in /home/jagdpanther/EPAM/snaketests/venv/lib/python3.8/site-packages/flask/app.py:1457]
Traceback (most recent call last):
  File "/home/jagdpanther/EPAM/snaketests/venv/lib/python3.8/site-packages/sqlalchemy/engine/base.py", line 1802, in _execute_context
    self.dialect.do_execute(
  File "/home/jagdpanther/EPAM/snaketests/venv/lib/python3.8/site-packages/sqlalchemy/engine/default.py", line 719, in do_execute
    cursor.execute(statement, parameters)
psycopg2.errors.UniqueViolation: duplicate key value violates unique constraint "user_email_key"
DETAIL:  Key (email)=(term@cmd.win) already exists.


The above exception was the direct cause of the following exception:

Traceback (most recent call last):
  File "/home/jagdpanther/EPAM/snaketests/venv/lib/python3.8/site-packages/flask/app.py", line 2073, in wsgi_app
    response = self.full_dispatch_request()
  File "/home/jagdpanther/EPAM/snaketests/venv/lib/python3.8/site-packages/flask/app.py", line 1518, in full_dispatch_request
    rv = self.handle_user_exception(e)
  File "/home/jagdpanther/EPAM/snaketests/venv/lib/python3.8/site-packages/flask_restful/__init__.py", line 271, in error_router
    return original_handler(e)
  File "/home/jagdpanther/EPAM/snaketests/venv/lib/python3.8/site-packages/flask_restful/__init__.py", line 271, in error_router
    return original_handler(e)
  File "/home/jagdpanther/EPAM/snaketests/venv/lib/python3.8/site-packages/flask/app.py", line 1516, in full_dispatch_request
    rv = self.dispatch_request()
  File "/home/jagdpanther/EPAM/snaketests/venv/lib/python3.8/site-packages/flask/app.py", line 1502, in dispatch_request
    return self.ensure_sync(self.view_functions[rule.endpoint])(**req.view_args)
  File "/home/jagdpanther/EPAM/snaketests/src/auth/routes.py", line 34, in register_page
    db.session.commit()
  File "<string>", line 2, in commit
  File "/home/jagdpanther/EPAM/snaketests/venv/lib/python3.8/site-packages/sqlalchemy/orm/session.py", line 1428, in commit
    self._transaction.commit(_to_root=self.future)
  File "/home/jagdpanther/EPAM/snaketests/venv/lib/python3.8/site-packages/sqlalchemy/orm/session.py", line 829, in commit
    self._prepare_impl()
  File "/home/jagdpanther/EPAM/snaketests/venv/lib/python3.8/site-packages/sqlalchemy/orm/session.py", line 808, in _prepare_impl
    self.session.flush()
  File "/home/jagdpanther/EPAM/snaketests/venv/lib/python3.8/site-packages/sqlalchemy/orm/session.py", line 3345, in flush
    self._flush(objects)
  File "/home/jagdpanther/EPAM/snaketests/venv/lib/python3.8/site-packages/sqlalchemy/orm/session.py", line 3485, in _flush
    transaction.rollback(_capture_exception=True)
  File "/home/jagdpanther/EPAM/snaketests/venv/lib/python3.8/site-packages/sqlalchemy/util/langhelpers.py", line 70, in __exit__
    compat.raise_(
  File "/home/jagdpanther/EPAM/snaketests/venv/lib/python3.8/site-packages/sqlalchemy/util/compat.py", line 207, in raise_
    raise exception
  File "/home/jagdpanther/EPAM/snaketests/venv/lib/python3.8/site-packages/sqlalchemy/orm/session.py", line 3445, in _flush
    flush_context.execute()
  File "/home/jagdpanther/EPAM/snaketests/venv/lib/python3.8/site-packages/sqlalchemy/orm/unitofwork.py", line 456, in execute
    rec.execute(self)
  File "/home/jagdpanther/EPAM/snaketests/venv/lib/python3.8/site-packages/sqlalchemy/orm/unitofwork.py", line 630, in execute
    util.preloaded.orm_persistence.save_obj(
  File "/home/jagdpanther/EPAM/snaketests/venv/lib/python3.8/site-packages/sqlalchemy/orm/persistence.py", line 244, in save_obj
    _emit_insert_statements(
  File "/home/jagdpanther/EPAM/snaketests/venv/lib/python3.8/site-packages/sqlalchemy/orm/persistence.py", line 1221, in _emit_insert_statements
    result = connection._execute_20(
  File "/home/jagdpanther/EPAM/snaketests/venv/lib/python3.8/site-packages/sqlalchemy/engine/base.py", line 1614, in _execute_20
    return meth(self, args_10style, kwargs_10style, execution_options)
  File "/home/jagdpanther/EPAM/snaketests/venv/lib/python3.8/site-packages/sqlalchemy/sql/elements.py", line 325, in _execute_on_connection
    return connection._execute_clauseelement(
  File "/home/jagdpanther/EPAM/snaketests/venv/lib/python3.8/site-packages/sqlalchemy/engine/base.py", line 1481, in _execute_clauseelement
    ret = self._execute_context(
  File "/home/jagdpanther/EPAM/snaketests/venv/lib/python3.8/site-packages/sqlalchemy/engine/base.py", line 1845, in _execute_context
    self._handle_dbapi_exception(
  File "/home/jagdpanther/EPAM/snaketests/venv/lib/python3.8/site-packages/sqlalchemy/engine/base.py", line 2026, in _handle_dbapi_exception
    util.raise_(
  File "/home/jagdpanther/EPAM/snaketests/venv/lib/python3.8/site-packages/sqlalchemy/util/compat.py", line 207, in raise_
    raise exception
  File "/home/jagdpanther/EPAM/snaketests/venv/lib/python3.8/site-packages/sqlalchemy/engine/base.py", line 1802, in _execute_context
    self.dialect.do_execute(
  File "/home/jagdpanther/EPAM/snaketests/venv/lib/python3.8/site-packages/sqlalchemy/engine/default.py", line 719, in do_execute
    cursor.execute(statement, parameters)
sqlalchemy.exc.IntegrityError: (psycopg2.errors.UniqueViolation) duplicate key value violates unique constraint "user_email_key"
DETAIL:  Key (email)=(term@cmd.win) already exists.

[SQL: INSERT INTO "user" (uuid, first_name, last_name, username, email, image, password_hash, is_superuser) VALUES (%(uuid)s, %(first_name)s, %(last_name)s, %(username)s, %(email)s, %(image)s, %(password_hash)s, %(is_superuser)s) RETURNING "user".id]
[parameters: {'uuid': UUID('a6040b1d-f14c-4580-9822-ee13b381979c'), 'first_name': '', 'last_name': '', 'username': 'blah', 'email': 'term@cmd.win', 'image': 'default.png', 'password_hash': '$2b$12$QtGrD/WFdYEFJVJD3svAL.94.ZjaNi584z4eairkYzHjdtc/VZ5HS', 'is_superuser': False}]
(Background on this error at: https://sqlalche.me/e/14/gkpj)

2022-01-01 14:03:02,268 INFO: 
APPLICATION HAS BEEN DEPLOYED [in /home/jagdpanther/EPAM/snaketests/src/__init__.py:115]

2022-01-01 14:03:52,500 INFO: 
APPLICATION HAS BEEN DEPLOYED [in /home/jagdpanther/EPAM/snaketests/src/__init__.py:115]

2022-01-01 14:04:00,593 INFO: 
APPLICATION HAS BEEN DEPLOYED [in /home/jagdpanther/EPAM/snaketests/src/__init__.py:115]

2022-01-01 14:04:36,841 INFO: 
APPLICATION HAS BEEN DEPLOYED [in /home/jagdpanther/EPAM/snaketests/src/__init__.py:115]

2022-01-01 14:05:03,326 ERROR: 
Exception on /auth/register [POST] [in /home/jagdpanther/EPAM/snaketests/venv/lib/python3.8/site-packages/flask/app.py:1457]
Traceback (most recent call last):
  File "/home/jagdpanther/EPAM/snaketests/venv/lib/python3.8/site-packages/sqlalchemy/engine/base.py", line 1802, in _execute_context
    self.dialect.do_execute(
  File "/home/jagdpanther/EPAM/snaketests/venv/lib/python3.8/site-packages/sqlalchemy/engine/default.py", line 719, in do_execute
    cursor.execute(statement, parameters)
psycopg2.errors.UniqueViolation: duplicate key value violates unique constraint "user_username_key"
DETAIL:  Key (username)=(terminal) already exists.


The above exception was the direct cause of the following exception:

Traceback (most recent call last):
  File "/home/jagdpanther/EPAM/snaketests/venv/lib/python3.8/site-packages/flask/app.py", line 2073, in wsgi_app
    response = self.full_dispatch_request()
  File "/home/jagdpanther/EPAM/snaketests/venv/lib/python3.8/site-packages/flask/app.py", line 1518, in full_dispatch_request
    rv = self.handle_user_exception(e)
  File "/home/jagdpanther/EPAM/snaketests/venv/lib/python3.8/site-packages/flask_restful/__init__.py", line 271, in error_router
    return original_handler(e)
  File "/home/jagdpanther/EPAM/snaketests/venv/lib/python3.8/site-packages/flask_restful/__init__.py", line 271, in error_router
    return original_handler(e)
  File "/home/jagdpanther/EPAM/snaketests/venv/lib/python3.8/site-packages/flask/app.py", line 1516, in full_dispatch_request
    rv = self.dispatch_request()
  File "/home/jagdpanther/EPAM/snaketests/venv/lib/python3.8/site-packages/flask/app.py", line 1502, in dispatch_request
    return self.ensure_sync(self.view_functions[rule.endpoint])(**req.view_args)
  File "/home/jagdpanther/EPAM/snaketests/src/auth/routes.py", line 34, in register_page
    db.session.commit()
  File "<string>", line 2, in commit
  File "/home/jagdpanther/EPAM/snaketests/venv/lib/python3.8/site-packages/sqlalchemy/orm/session.py", line 1428, in commit
    self._transaction.commit(_to_root=self.future)
  File "/home/jagdpanther/EPAM/snaketests/venv/lib/python3.8/site-packages/sqlalchemy/orm/session.py", line 829, in commit
    self._prepare_impl()
  File "/home/jagdpanther/EPAM/snaketests/venv/lib/python3.8/site-packages/sqlalchemy/orm/session.py", line 808, in _prepare_impl
    self.session.flush()
  File "/home/jagdpanther/EPAM/snaketests/venv/lib/python3.8/site-packages/sqlalchemy/orm/session.py", line 3345, in flush
    self._flush(objects)
  File "/home/jagdpanther/EPAM/snaketests/venv/lib/python3.8/site-packages/sqlalchemy/orm/session.py", line 3485, in _flush
    transaction.rollback(_capture_exception=True)
  File "/home/jagdpanther/EPAM/snaketests/venv/lib/python3.8/site-packages/sqlalchemy/util/langhelpers.py", line 70, in __exit__
    compat.raise_(
  File "/home/jagdpanther/EPAM/snaketests/venv/lib/python3.8/site-packages/sqlalchemy/util/compat.py", line 207, in raise_
    raise exception
  File "/home/jagdpanther/EPAM/snaketests/venv/lib/python3.8/site-packages/sqlalchemy/orm/session.py", line 3445, in _flush
    flush_context.execute()
  File "/home/jagdpanther/EPAM/snaketests/venv/lib/python3.8/site-packages/sqlalchemy/orm/unitofwork.py", line 456, in execute
    rec.execute(self)
  File "/home/jagdpanther/EPAM/snaketests/venv/lib/python3.8/site-packages/sqlalchemy/orm/unitofwork.py", line 630, in execute
    util.preloaded.orm_persistence.save_obj(
  File "/home/jagdpanther/EPAM/snaketests/venv/lib/python3.8/site-packages/sqlalchemy/orm/persistence.py", line 244, in save_obj
    _emit_insert_statements(
  File "/home/jagdpanther/EPAM/snaketests/venv/lib/python3.8/site-packages/sqlalchemy/orm/persistence.py", line 1221, in _emit_insert_statements
    result = connection._execute_20(
  File "/home/jagdpanther/EPAM/snaketests/venv/lib/python3.8/site-packages/sqlalchemy/engine/base.py", line 1614, in _execute_20
    return meth(self, args_10style, kwargs_10style, execution_options)
  File "/home/jagdpanther/EPAM/snaketests/venv/lib/python3.8/site-packages/sqlalchemy/sql/elements.py", line 325, in _execute_on_connection
    return connection._execute_clauseelement(
  File "/home/jagdpanther/EPAM/snaketests/venv/lib/python3.8/site-packages/sqlalchemy/engine/base.py", line 1481, in _execute_clauseelement
    ret = self._execute_context(
  File "/home/jagdpanther/EPAM/snaketests/venv/lib/python3.8/site-packages/sqlalchemy/engine/base.py", line 1845, in _execute_context
    self._handle_dbapi_exception(
  File "/home/jagdpanther/EPAM/snaketests/venv/lib/python3.8/site-packages/sqlalchemy/engine/base.py", line 2026, in _handle_dbapi_exception
    util.raise_(
  File "/home/jagdpanther/EPAM/snaketests/venv/lib/python3.8/site-packages/sqlalchemy/util/compat.py", line 207, in raise_
    raise exception
  File "/home/jagdpanther/EPAM/snaketests/venv/lib/python3.8/site-packages/sqlalchemy/engine/base.py", line 1802, in _execute_context
    self.dialect.do_execute(
  File "/home/jagdpanther/EPAM/snaketests/venv/lib/python3.8/site-packages/sqlalchemy/engine/default.py", line 719, in do_execute
    cursor.execute(statement, parameters)
sqlalchemy.exc.IntegrityError: (psycopg2.errors.UniqueViolation) duplicate key value violates unique constraint "user_username_key"
DETAIL:  Key (username)=(terminal) already exists.

[SQL: INSERT INTO "user" (uuid, first_name, last_name, username, email, image, password_hash, is_superuser) VALUES (%(uuid)s, %(first_name)s, %(last_name)s, %(username)s, %(email)s, %(image)s, %(password_hash)s, %(is_superuser)s) RETURNING "user".id]
[parameters: {'uuid': UUID('5e654226-4042-4cfa-ac67-32c39543b7da'), 'first_name': '', 'last_name': '', 'username': 'terminal', 'email': 'foo@bar.com', 'image': 'default.png', 'password_hash': '$2b$12$r1dzFK3HL1YbuIUCnFf6QuzjbY6n2/YevcxqmFYXAQzNSHNIKOoxu', 'is_superuser': False}]
(Background on this error at: https://sqlalche.me/e/14/gkpj)

2022-01-01 14:05:41,052 INFO: 
APPLICATION HAS BEEN DEPLOYED [in /home/jagdpanther/EPAM/snaketests/src/__init__.py:115]

2022-01-01 14:05:41,629 INFO: 
APPLICATION HAS BEEN DEPLOYED [in /home/jagdpanther/EPAM/snaketests/src/__init__.py:115]

2022-01-01 14:05:48,207 INFO: 
APPLICATION HAS BEEN DEPLOYED [in /home/jagdpanther/EPAM/snaketests/src/__init__.py:115]

2022-01-01 14:05:48,716 INFO: 
APPLICATION HAS BEEN DEPLOYED [in /home/jagdpanther/EPAM/snaketests/src/__init__.py:115]

2022-01-01 14:08:52,748 INFO: 
APPLICATION HAS BEEN DEPLOYED [in /home/jagdpanther/EPAM/snaketests/src/__init__.py:115]

2022-01-01 14:11:03,670 INFO: 
APPLICATION HAS BEEN DEPLOYED [in /home/jagdpanther/EPAM/snaketests/src/__init__.py:115]

2022-01-01 14:13:14,584 INFO: 
APPLICATION HAS BEEN DEPLOYED [in /home/jagdpanther/EPAM/snaketests/src/__init__.py:115]

2022-01-01 14:28:14,520 INFO: 
APPLICATION HAS BEEN DEPLOYED [in /home/jagdpanther/EPAM/snaketests/src/__init__.py:115]

2022-01-01 14:38:11,232 INFO: 
APPLICATION HAS BEEN DEPLOYED [in /home/jagdpanther/EPAM/snaketests/src/__init__.py:115]

2022-01-01 15:00:18,023 INFO: 
APPLICATION HAS BEEN DEPLOYED [in /home/jagdpanther/EPAM/snaketests/src/__init__.py:115]

2022-01-01 15:16:17,451 INFO: 
APPLICATION HAS BEEN DEPLOYED [in /home/jagdpanther/EPAM/snaketests/src/__init__.py:115]

2022-01-01 15:20:11,594 INFO: 
APPLICATION HAS BEEN DEPLOYED [in /home/jagdpanther/EPAM/snaketests/src/__init__.py:115]

2022-01-01 15:37:57,033 INFO: 
APPLICATION HAS BEEN DEPLOYED [in /home/jagdpanther/EPAM/snaketests/src/__init__.py:115]

2022-01-01 15:37:57,033 INFO: 
APPLICATION HAS BEEN DEPLOYED [in /home/jagdpanther/EPAM/snaketests/src/__init__.py:115]

2022-01-01 15:37:57,091 INFO: 
APPLICATION HAS BEEN DEPLOYED [in /home/jagdpanther/EPAM/snaketests/src/__init__.py:115]

2022-01-01 16:05:42,225 INFO: 
APPLICATION HAS BEEN DEPLOYED [in /home/jagdpanther/EPAM/snaketests/src/__init__.py:115]

2022-01-01 16:05:56,388 INFO: 
APPLICATION HAS BEEN DEPLOYED [in /home/jagdpanther/EPAM/snaketests/src/__init__.py:115]

2022-01-01 16:08:38,626 INFO: 
APPLICATION HAS BEEN DEPLOYED [in /home/jagdpanther/EPAM/snaketests/src/__init__.py:115]

2022-01-01 16:08:38,632 INFO: 
APPLICATION HAS BEEN DEPLOYED [in /home/jagdpanther/EPAM/snaketests/src/__init__.py:115]

2022-01-01 16:08:38,654 INFO: 
APPLICATION HAS BEEN DEPLOYED [in /home/jagdpanther/EPAM/snaketests/src/__init__.py:115]

2022-01-09 23:12:12,413 INFO: 
APPLICATION HAS BEEN DEPLOYED [in /home/jagdpanther/EPAM/snaketests/src/__init__.py:116]

2022-01-09 23:12:12,520 INFO: 
APPLICATION HAS BEEN DEPLOYED [in /home/jagdpanther/EPAM/snaketests/src/__init__.py:116]

2022-01-09 23:12:12,613 INFO: 
APPLICATION HAS BEEN DEPLOYED [in /home/jagdpanther/EPAM/snaketests/src/__init__.py:116]

2022-01-09 23:12:12,740 INFO: 
APPLICATION HAS BEEN DEPLOYED [in /home/jagdpanther/EPAM/snaketests/src/__init__.py:116]

2022-01-11 16:26:02,614 INFO: 
APPLICATION HAS BEEN DEPLOYED [in /home/jagdpanther/EPAM/snaketests/src/__init__.py:116]

2022-01-11 16:26:02,614 INFO: 
APPLICATION HAS BEEN DEPLOYED [in /home/jagdpanther/EPAM/snaketests/src/__init__.py:116]

2022-01-11 16:26:02,614 INFO: 
APPLICATION HAS BEEN DEPLOYED [in /home/jagdpanther/EPAM/snaketests/src/__init__.py:116]

2022-01-11 16:26:02,615 INFO: 
APPLICATION HAS BEEN DEPLOYED [in /home/jagdpanther/EPAM/snaketests/src/__init__.py:116]

2022-01-11 16:26:03,368 INFO: 
APPLICATION HAS BEEN DEPLOYED [in /home/jagdpanther/EPAM/snaketests/src/__init__.py:116]

2022-01-11 16:26:03,441 INFO: 
APPLICATION HAS BEEN DEPLOYED [in /home/jagdpanther/EPAM/snaketests/src/__init__.py:116]

2022-01-11 16:26:03,502 INFO: 
APPLICATION HAS BEEN DEPLOYED [in /home/jagdpanther/EPAM/snaketests/src/__init__.py:116]

2022-01-11 16:26:03,555 INFO: 
APPLICATION HAS BEEN DEPLOYED [in /home/jagdpanther/EPAM/snaketests/src/__init__.py:116]

2022-01-11 23:31:32,494 INFO: 
APPLICATION HAS BEEN DEPLOYED [in /home/jagdpanther/EPAM/snaketests/src/__init__.py:116]

2022-01-11 23:31:32,507 INFO: 
APPLICATION HAS BEEN DEPLOYED [in /home/jagdpanther/EPAM/snaketests/src/__init__.py:116]

2022-01-11 23:31:32,507 INFO: 
APPLICATION HAS BEEN DEPLOYED [in /home/jagdpanther/EPAM/snaketests/src/__init__.py:116]

2022-01-11 23:31:32,512 INFO: 
APPLICATION HAS BEEN DEPLOYED [in /home/jagdpanther/EPAM/snaketests/src/__init__.py:116]

2022-01-11 23:31:32,515 INFO: 
APPLICATION HAS BEEN DEPLOYED [in /home/jagdpanther/EPAM/snaketests/src/__init__.py:116]

2022-01-11 23:31:32,531 INFO: 
APPLICATION HAS BEEN DEPLOYED [in /home/jagdpanther/EPAM/snaketests/src/__init__.py:116]

2022-01-11 23:31:32,531 INFO: 
APPLICATION HAS BEEN DEPLOYED [in /home/jagdpanther/EPAM/snaketests/src/__init__.py:116]

2022-01-11 23:31:32,537 INFO: 
APPLICATION HAS BEEN DEPLOYED [in /home/jagdpanther/EPAM/snaketests/src/__init__.py:116]
